<robot name="Gantry_CAD">

	<link name="world">
	</link>

	<joint name="base_joint" type="fixed">
		<!-- because of how the STL has been loaded in, have to rotate by 90 deg and translate slightly-->
		<origin xyz="0 0 0" rpy="1.570796327 0 1.570796327"/>
		<parent link="world"/>
		<child link="base_link"/>
	</joint>

	<!-- links the world to the corner (origin) of the gantry frame-->
    <link name="base_link">
        <visual>
	        <origin xyz="-0.01282036 -0.00464999676 -0.00316703" rpy="0 0 0"/>
            <geometry>
		        <mesh filename="GANTRY_FRAME.STL" scale="0.001 0.001 0.001"/>
            </geometry>
            <material name="grey">
                <color rgba="0.5 0.5 0.5 1"/> 
            </material>
        </visual>
        <collision>
			<origin xyz="-0.01282036 -0.00465 -0.00316703" rpy="0 0 0"/>
            <geometry>
				<mesh filename="GANTRY_FRAME.STL" scale="0.001 0.001 0.001"/>
            </geometry>
        </collision>
        <inertial>
            <mass value="1.0"/> <!-- Mass in kilograms -->
            <inertia ixx="0.1" ixy="0.0" ixz="0.0" iyy="0.1" iyz="0.0" izz="0.1"/>
        </inertial>
    </link>

	<joint name="yaxis_joint" type="prismatic">
		
		<origin xyz="0.28605 0.515 0.3227" rpy="0 0 0"/>
		<parent link="base_link"/>
		<child link="yaxis_link"/>

		<axis xyz="0 0 1"/>
		<limit lower="0.038" upper="1.35" velocity="100" effort="100"/>		
	</joint>

	<link name="yaxis_link">
		<visual>
			<origin xyz="-0.00995999 -0.05 -0.52094043" rpy="0 0 0"/>
			<geometry>
				<mesh filename="YAXIS.STL" scale="0.001 0.001 0.001"/>
			</geometry>
			<material name="red">
				<color rgba="1 0 0 1"/>
			</material>
		</visual>
		<collision>
			<geometry>
				<box size="1 1 1"/>
			</geometry>
		</collision>
		<inertial>
			<mass value="1.0"/>
			<!-- Mass in kilograms -->
			<inertia ixx="0.1" ixy="0.0" ixz="0.0" iyy="0.1" iyz="0.0" izz="0.1"/>
		</inertial>
	</link>

	<joint name="zaxis_joint" type="prismatic">

		<origin xyz="0.882 0.5385 0.042" rpy="0 0 0"/>
		<parent link="yaxis_link"/>
		<child link="zaxis_link"/>

		<axis xyz="1 0 0"/>
		<limit lower="-0.72" upper="-0.12" velocity="100" effort="100"/>
	</joint>

	<link name="zaxis_link">
		<visual>
			<origin xyz="-0.00998167 -1.00461999512 -0.56970911" rpy="0 0 0"/>
			<geometry>
				<mesh filename="ZAXIS.STL" scale="0.001 0.001 0.001"/>
			</geometry>
			<material name="green">
				<color rgba="0 1 0 1"/>
			</material>
		</visual>
		<collision>
			<geometry>
				<box size="1 1 1"/>
			</geometry>
		</collision>
		<inertial>
			<mass value="1.0"/>
			<!-- Mass in kilograms -->
			<inertia ixx="0.1" ixy="0.0" ixz="0.0" iyy="0.1" iyz="0.0" izz="0.1"/>
		</inertial>
	</link>

	<joint name="gimbal_interface_joint" type="prismatic">

		<origin xyz="0 -0.96491 0.117" rpy="0 0 0"/>
		<parent link="zaxis_link"/>
		<child link="gimbal_interface_link"/>

		<axis xyz="0 1 0"/>
		<limit lower="0.15" upper="0.902" velocity="100" effort="100"/>
	</joint>

	<link name="gimbal_interface_link">
		<visual>
			<origin xyz="-0.00594166 -0.16590892029 -0.68670911" rpy="0 0 0"/>
			<geometry>
				<mesh filename="GIMBAL_INTERFACE.STL" scale="0.001 0.001 0.001"/>
			</geometry>
			<material name="blue">
				<color rgba="0 0 1 1"/>
			</material>
		</visual>
		<collision>
			<geometry>
				<box size="1 1 1"/>
			</geometry>
		</collision>
		<inertial>
			<mass value="1.0"/>
			<!-- Mass in kilograms -->
			<inertia ixx="0.1" ixy="0.0" ixz="0.0" iyy="0.1" iyz="0.0" izz="0.1"/>
		</inertial>
	</link>

	<joint name="yaw_axis_joint" type="fixed">
		<origin xyz="0.002 -0.055 0" rpy="0 1.570796327 0"/>
		<parent link="gimbal_interface_link"/>
		<child link="yaw_axis_link"/>

	</joint>

	<link name="yaw_axis_link">
		<visual>
			<origin xyz="-0.76425525 -0.8042663 -1.21712" rpy="0 0 0"/>
			<geometry>
				<mesh filename="YAWAXIS.STL" scale="0.001 0.001 0.001"/>
			</geometry>
			<material name="yellow">
				<color rgba="1 1 0 1"/>
			</material>
		</visual>
		<collision>
			<geometry>
				<box size="1 1 1"/>
			</geometry>
		</collision>
		<inertial>
			<mass value="1.0"/>
			<!-- Mass in kilograms -->
			<inertia ixx="0.1" ixy="0.0" ixz="0.0" iyy="0.1" iyz="0.0" izz="0.1"/>
		</inertial>
	</link>

	<joint name="pitch_axis_joint" type="revolute">
		<!-- left/right , up/down, forwards/backwards-->
		<origin xyz="-0.155 0.0205 0.0625" rpy="0 0 0"/>
		<parent link="yaw_axis_link"/>
		<child link="pitch_axis_link"/>

		<axis xyz="0 1 0"/>
		<limit effort="100" velocity="2" lower="-1.39626340159546" upper="1.39626340159546"/>
	</joint>

	<link name="pitch_axis_link">
		<visual>
			<origin xyz="-0.60925525 -0.8247663 -1.27962" rpy="0 0 0"/>
			<geometry>
				<mesh filename="PITCHAXIS.STL" scale="0.001 0.001 0.001"/>
			</geometry>
			<material name="cyan">
				<color rgba="0 1 1 1"/>
			</material>
		</visual>
		<collision>
			<geometry>
				<box size="1 1 1"/>
			</geometry>
		</collision>
		<inertial>
			<mass value="1.0"/>
			<inertia ixx="0.1" ixy="0.0" ixz="0.0" iyy="0.1" iyz="0.0" izz="0.1"/>
		</inertial>
	</link>

	<joint name="roll_axis_joint" type="revolute">
		<origin xyz="0 0.147789 -0.0715" rpy="0 0 0"/>
		<parent link="pitch_axis_link"/>
		<child link="roll_axis_link"/>

		<axis xyz="0 0 1"/>
		<limit effort="100" velocity="2" lower="-1.48352986419518" upper="1.48352986419518"/>
	</joint>

	<link name="roll_axis_link">
		<visual>
			<origin xyz="-0.60925526 -0.97255529 -1.20812" rpy="0 0 0"/>
			<geometry>
				<mesh filename="ROLLAXIS.STL" scale="0.001 0.001 0.001"/>
			</geometry>
			<material name="magenta">
				<color rgba="1 0 1 1"/>
			</material>
		</visual>
		<collision>
			<geometry>
				<box size="1 1 1"/>
			</geometry>
		</collision>
		<inertial>
			<mass value="1.0"/>
			<inertia ixx="0.1" ixy="0.0" ixz="0.0" iyy="0.1" iyz="0.0" izz="0.1"/>
		</inertial>
	</link>

	<joint name="end_eff_interface_joint" type="revolute">
		<origin xyz="-0.0374949 0.0006177 0.0715" rpy="0 0 -1.570796327"/>
		<parent link="roll_axis_link"/>
		<child link="end_eff_interface_link"/>

		<axis xyz="0 1 0"/>
		<limit effort="100" velocity="2" lower="-3.141592654" upper="3.141592654"/>
	</joint>

	<link name="end_eff_interface_link">
		<visual>
			<origin xyz="-0.025 0 -0.025" rpy="0 0 0"/>
			<geometry>
				<mesh filename="END_EFF_INTERFACE.STL" scale="0.001 0.001 0.001"/>
			</geometry>
			<material name="orange">
				<color rgba="1 0.5 0 1"/>
			</material>
		</visual>
		<collision>
			<geometry>
				<box size="1 1 1"/>
			</geometry>
		</collision>
		<inertial>
			<mass value="1.0"/>
			<inertia ixx="0.1" ixy="0.0" ixz="0.0" iyy="0.1" iyz="0.0" izz="0.1"/>
		</inertial>
	</link>

	<joint name="end_eff_joint" type="fixed">
		<origin xyz="0 -0.053 0" rpy="0 -1.570796327 3.14159265359"/>
		<parent link="end_eff_interface_link"/>
		<child link="end_eff_link"/>
	</joint>

	<link name="end_eff_link">
		<visual>
			<origin xyz="-0.58582452 -0.91537085 -1.31050378" rpy="0 0 0"/>
			<geometry>
				<mesh filename="END_EFF.STL" scale="0.001 0.001 0.001"/>
			</geometry>
			<material name="white">
				<color rgba="1 1 1 1"/>
			</material>
		</visual>
		<collision>
			<origin xyz="-0.58582452 -0.91537085 -1.31050378" rpy="0 0 0"/>			
			<geometry>
				<mesh filename="END_EFF.STL" scale="0.001 0.001 0.001"/>
			</geometry>
		</collision>
		<inertial>
			<mass value="1.0"/>
			<!-- Mass in kilograms -->
			<inertia ixx="0.1" ixy="0.0" ixz="0.0" iyy="0.1" iyz="0.0" izz="0.1"/>
		</inertial>
	</link>

	<joint name="target_frame_joint" type="fixed">
		<origin xyz="1.01205 0.485 1.8327" rpy="0 3.14159265359 0"/>
		<parent link="base_link"/>
		<child link="target_frame_link"/>
	</joint>

	<link name="target_frame_link">
		<visual>
			<origin xyz="-0.36851358 -0.64274487 -1.27590442" rpy="0 0 0"/>
			<geometry>
				<mesh filename="TARGET_FRAME.STL" scale="0.001 0.001 0.001"/>
			</geometry>
			<material name="gold">
				<color rgba="0.83 0.69 0.22 1.0"/>
			</material>
		</visual>
		<collision>
			<origin xyz="-0.36851358 -0.64274487 -1.27590442" rpy="0 0 0"/>
			<geometry>
				<mesh filename="TARGET_FRAME.STL" scale="0.001 0.001 0.001"/>
			</geometry>
		</collision>
		<inertial>
			<mass value="1.0"/>
			<!-- Mass in kilograms -->
			<inertia ixx="0.1" ixy="0.0" ixz="0.0" iyy="0.1" iyz="0.0" izz="0.1"/>
		</inertial>
	</link>

</robot>